Failure # 1 (occurred at 2021-05-24_10-58-25)
Traceback (most recent call last):
  File "/Users/beantown/opt/anaconda3/envs/PuzzleSolver/lib/python3.8/site-packages/ray/tune/trial_runner.py", line 702, in _process_trial
    results = self.trial_executor.fetch_result(trial)
  File "/Users/beantown/opt/anaconda3/envs/PuzzleSolver/lib/python3.8/site-packages/ray/tune/ray_trial_executor.py", line 686, in fetch_result
    result = ray.get(trial_future[0], timeout=DEFAULT_GET_TIMEOUT)
  File "/Users/beantown/opt/anaconda3/envs/PuzzleSolver/lib/python3.8/site-packages/ray/_private/client_mode_hook.py", line 47, in wrapper
    return func(*args, **kwargs)
  File "/Users/beantown/opt/anaconda3/envs/PuzzleSolver/lib/python3.8/site-packages/ray/worker.py", line 1481, in get
    raise value.as_instanceof_cause()
ray.exceptions.RayTaskError: [36mray::ImplicitFunc.train_buffered()[39m (pid=51136, ip=192.168.2.103)
  File "python/ray/_raylet.pyx", line 449, in ray._raylet.execute_task.function_executor
  File "/Users/beantown/opt/anaconda3/envs/PuzzleSolver/lib/python3.8/site-packages/ray/_private/function_manager.py", line 556, in actor_method_executor
    return method(__ray_actor, *args, **kwargs)
  File "/Users/beantown/opt/anaconda3/envs/PuzzleSolver/lib/python3.8/site-packages/ray/tune/trainable.py", line 173, in train_buffered
    result = self.train()
  File "/Users/beantown/opt/anaconda3/envs/PuzzleSolver/lib/python3.8/site-packages/ray/tune/trainable.py", line 232, in train
    result = self.step()
  File "/Users/beantown/opt/anaconda3/envs/PuzzleSolver/lib/python3.8/site-packages/ray/tune/function_runner.py", line 348, in step
    result = self._results_queue.get(
  File "/Users/beantown/opt/anaconda3/envs/PuzzleSolver/lib/python3.8/queue.py", line 179, in get
    self.not_empty.wait(remaining)
  File "/Users/beantown/opt/anaconda3/envs/PuzzleSolver/lib/python3.8/threading.py", line 306, in wait
    gotit = waiter.acquire(True, timeout)
KeyboardInterrupt

During handling of the above exception, another exception occurred:

[36mray::ImplicitFunc.train_buffered()[39m (pid=51136, ip=192.168.2.103)
  File "python/ray/_raylet.pyx", line 488, in ray._raylet.execute_task
  File "python/ray/_raylet.pyx", line 522, in ray._raylet.execute_task
ray.exceptions.TaskCancelledError: Task: TaskID(e320f439b49c5157d2f7d00f55c76fdca698e29701000000) was cancelled

