Failure # 1 (occurred at 2021-06-18_17-42-48)
Traceback (most recent call last):
  File "/Users/beantown/opt/anaconda3/envs/PuzzleSolver/lib/python3.8/site-packages/ray/tune/trial_runner.py", line 718, in _process_trial
    results = self.trial_executor.fetch_result(trial)
  File "/Users/beantown/opt/anaconda3/envs/PuzzleSolver/lib/python3.8/site-packages/ray/tune/ray_trial_executor.py", line 688, in fetch_result
    result = ray.get(trial_future[0], timeout=DEFAULT_GET_TIMEOUT)
  File "/Users/beantown/opt/anaconda3/envs/PuzzleSolver/lib/python3.8/site-packages/ray/_private/client_mode_hook.py", line 62, in wrapper
    return func(*args, **kwargs)
  File "/Users/beantown/opt/anaconda3/envs/PuzzleSolver/lib/python3.8/site-packages/ray/worker.py", line 1494, in get
    raise value.as_instanceof_cause()
ray.exceptions.RayTaskError(TuneError): [36mray::ImplicitFunc.train_buffered()[39m (pid=65491, ip=192.168.2.103)
  File "python/ray/_raylet.pyx", line 501, in ray._raylet.execute_task
  File "python/ray/_raylet.pyx", line 451, in ray._raylet.execute_task.function_executor
  File "/Users/beantown/opt/anaconda3/envs/PuzzleSolver/lib/python3.8/site-packages/ray/_private/function_manager.py", line 563, in actor_method_executor
    return method(__ray_actor, *args, **kwargs)
  File "/Users/beantown/opt/anaconda3/envs/PuzzleSolver/lib/python3.8/site-packages/ray/tune/trainable.py", line 173, in train_buffered
    result = self.train()
  File "/Users/beantown/opt/anaconda3/envs/PuzzleSolver/lib/python3.8/site-packages/ray/tune/trainable.py", line 232, in train
    result = self.step()
  File "/Users/beantown/opt/anaconda3/envs/PuzzleSolver/lib/python3.8/site-packages/ray/tune/function_runner.py", line 366, in step
    self._report_thread_runner_error(block=True)
  File "/Users/beantown/opt/anaconda3/envs/PuzzleSolver/lib/python3.8/site-packages/ray/tune/function_runner.py", line 512, in _report_thread_runner_error
    raise TuneError(
ray.tune.error.TuneError: Trial raised an exception. Traceback:
[36mray::ImplicitFunc.train_buffered()[39m (pid=65491, ip=192.168.2.103)
  File "/Users/beantown/opt/anaconda3/envs/PuzzleSolver/lib/python3.8/site-packages/ray/tune/function_runner.py", line 248, in run
    self._entrypoint()
  File "/Users/beantown/opt/anaconda3/envs/PuzzleSolver/lib/python3.8/site-packages/ray/tune/function_runner.py", line 315, in entrypoint
    return self._trainable_func(self.config, self._status_reporter,
  File "/Users/beantown/opt/anaconda3/envs/PuzzleSolver/lib/python3.8/site-packages/ray/tune/function_runner.py", line 580, in _trainable_func
    output = fn()
  File "/Users/beantown/opt/anaconda3/envs/PuzzleSolver/lib/python3.8/site-packages/ray/tune/utils/trainable.py", line 340, in _inner
    inner(config, checkpoint_dir=None)
  File "/Users/beantown/opt/anaconda3/envs/PuzzleSolver/lib/python3.8/site-packages/ray/tune/utils/trainable.py", line 331, in inner
    trainable(config, **fn_kwargs)
  File "/Users/beantown/PycharmProjects/jigsaw-puzzle-solver/src/Main.py", line 40, in training_function
    trainer.fit(model)
  File "/Users/beantown/opt/anaconda3/envs/PuzzleSolver/lib/python3.8/site-packages/mlflow/utils/autologging_utils/safety.py", line 489, in safe_patch_function
    patch_function(call_original, *args, **kwargs)
  File "/Users/beantown/opt/anaconda3/envs/PuzzleSolver/lib/python3.8/site-packages/mlflow/utils/autologging_utils/safety.py", line 240, in patch_with_managed_run
    result = patch_function(original, *args, **kwargs)
  File "/Users/beantown/opt/anaconda3/envs/PuzzleSolver/lib/python3.8/site-packages/mlflow/pytorch/_pytorch_autolog.py", line 303, in fit
    return _run_and_log_function(self, original, args, kwargs)
  File "/Users/beantown/opt/anaconda3/envs/PuzzleSolver/lib/python3.8/site-packages/mlflow/pytorch/_pytorch_autolog.py", line 295, in _run_and_log_function
    result = original(self, *args, **kwargs)
  File "/Users/beantown/opt/anaconda3/envs/PuzzleSolver/lib/python3.8/site-packages/mlflow/utils/autologging_utils/safety.py", line 445, in call_original
    original_result = original(*og_args, **og_kwargs)
  File "/Users/beantown/opt/anaconda3/envs/PuzzleSolver/lib/python3.8/site-packages/pytorch_lightning/trainer/trainer.py", line 458, in fit
    self._run(model)
  File "/Users/beantown/opt/anaconda3/envs/PuzzleSolver/lib/python3.8/site-packages/pytorch_lightning/trainer/trainer.py", line 715, in _run
    self.accelerator.setup(self, model)  # note: this sets up self.lightning_module
  File "/Users/beantown/opt/anaconda3/envs/PuzzleSolver/lib/python3.8/site-packages/pytorch_lightning/accelerators/cpu.py", line 39, in setup
    return super().setup(trainer, model)
  File "/Users/beantown/opt/anaconda3/envs/PuzzleSolver/lib/python3.8/site-packages/pytorch_lightning/accelerators/accelerator.py", line 92, in setup
    self.setup_optimizers(trainer)
  File "/Users/beantown/opt/anaconda3/envs/PuzzleSolver/lib/python3.8/site-packages/pytorch_lightning/accelerators/accelerator.py", line 374, in setup_optimizers
    optimizers, lr_schedulers, optimizer_frequencies = self.training_type_plugin.init_optimizers(
  File "/Users/beantown/opt/anaconda3/envs/PuzzleSolver/lib/python3.8/site-packages/pytorch_lightning/plugins/training_type/training_type_plugin.py", line 190, in init_optimizers
    return trainer.init_optimizers(model)
  File "/Users/beantown/opt/anaconda3/envs/PuzzleSolver/lib/python3.8/site-packages/pytorch_lightning/trainer/optimizers.py", line 34, in init_optimizers
    optim_conf = model.configure_optimizers()
  File "/Users/beantown/PycharmProjects/jigsaw-puzzle-solver/src/models/SiameseNetwork.py", line 111, in configure_optimizers
    optimizer = torch.optim.Adam(self.parameters(), lr=hyperparameters["lr"])
NameError: name 'hyperparameters' is not defined

