Failure # 1 (occurred at 2021-05-23_22-14-26)
Traceback (most recent call last):
  File "/Users/beantown/opt/anaconda3/envs/PuzzleSolver/lib/python3.8/site-packages/ray/tune/trial_runner.py", line 702, in _process_trial
    results = self.trial_executor.fetch_result(trial)
  File "/Users/beantown/opt/anaconda3/envs/PuzzleSolver/lib/python3.8/site-packages/ray/tune/ray_trial_executor.py", line 686, in fetch_result
    result = ray.get(trial_future[0], timeout=DEFAULT_GET_TIMEOUT)
  File "/Users/beantown/opt/anaconda3/envs/PuzzleSolver/lib/python3.8/site-packages/ray/_private/client_mode_hook.py", line 47, in wrapper
    return func(*args, **kwargs)
  File "/Users/beantown/opt/anaconda3/envs/PuzzleSolver/lib/python3.8/site-packages/ray/worker.py", line 1481, in get
    raise value.as_instanceof_cause()
ray.exceptions.RayTaskError(TuneError): [36mray::ImplicitFunc.train_buffered()[39m (pid=44452, ip=192.168.2.103)
  File "python/ray/_raylet.pyx", line 505, in ray._raylet.execute_task
  File "python/ray/_raylet.pyx", line 449, in ray._raylet.execute_task.function_executor
  File "/Users/beantown/opt/anaconda3/envs/PuzzleSolver/lib/python3.8/site-packages/ray/_private/function_manager.py", line 556, in actor_method_executor
    return method(__ray_actor, *args, **kwargs)
  File "/Users/beantown/opt/anaconda3/envs/PuzzleSolver/lib/python3.8/site-packages/ray/tune/trainable.py", line 173, in train_buffered
    result = self.train()
  File "/Users/beantown/opt/anaconda3/envs/PuzzleSolver/lib/python3.8/site-packages/ray/tune/trainable.py", line 232, in train
    result = self.step()
  File "/Users/beantown/opt/anaconda3/envs/PuzzleSolver/lib/python3.8/site-packages/ray/tune/function_runner.py", line 366, in step
    self._report_thread_runner_error(block=True)
  File "/Users/beantown/opt/anaconda3/envs/PuzzleSolver/lib/python3.8/site-packages/ray/tune/function_runner.py", line 512, in _report_thread_runner_error
    raise TuneError(
ray.tune.error.TuneError: Trial raised an exception. Traceback:
[36mray::ImplicitFunc.train_buffered()[39m (pid=44452, ip=192.168.2.103)
  File "/Users/beantown/opt/anaconda3/envs/PuzzleSolver/lib/python3.8/site-packages/ray/tune/function_runner.py", line 248, in run
    self._entrypoint()
  File "/Users/beantown/opt/anaconda3/envs/PuzzleSolver/lib/python3.8/site-packages/ray/tune/function_runner.py", line 315, in entrypoint
    return self._trainable_func(self.config, self._status_reporter,
  File "/Users/beantown/opt/anaconda3/envs/PuzzleSolver/lib/python3.8/site-packages/ray/tune/function_runner.py", line 580, in _trainable_func
    output = fn()
  File "/Users/beantown/opt/anaconda3/envs/PuzzleSolver/lib/python3.8/site-packages/ray/tune/utils/trainable.py", line 339, in _inner
    inner(config, checkpoint_dir=None)
  File "/Users/beantown/opt/anaconda3/envs/PuzzleSolver/lib/python3.8/site-packages/ray/tune/utils/trainable.py", line 330, in inner
    trainable(config, **fn_kwargs)
  File "/Users/beantown/PycharmProjects/jigsaw-puzzle-solver/src/Main.py", line 31, in training_function
    trainer.fit(model)
  File "/Users/beantown/opt/anaconda3/envs/PuzzleSolver/lib/python3.8/site-packages/pytorch_lightning/trainer/trainer.py", line 458, in fit
    self._run(model)
  File "/Users/beantown/opt/anaconda3/envs/PuzzleSolver/lib/python3.8/site-packages/pytorch_lightning/trainer/trainer.py", line 704, in _run
    self.data_connector.prepare_data(model)
  File "/Users/beantown/opt/anaconda3/envs/PuzzleSolver/lib/python3.8/site-packages/pytorch_lightning/trainer/connectors/data_connector.py", line 57, in prepare_data
    model.prepare_data()
  File "/Users/beantown/PycharmProjects/jigsaw-puzzle-solver/src/models/LightningMNISTClassifier.py", line 86, in prepare_data
    mnist_train = self.download_data(self.data_dir)
  File "/Users/beantown/PycharmProjects/jigsaw-puzzle-solver/src/models/LightningMNISTClassifier.py", line 83, in download_data
    return KMNIST(data_dir, train=True, download=True, transform=transform)
  File "/Users/beantown/opt/anaconda3/envs/PuzzleSolver/lib/python3.8/site-packages/torchvision/datasets/mnist.py", line 79, in __init__
    self.download()
  File "/Users/beantown/opt/anaconda3/envs/PuzzleSolver/lib/python3.8/site-packages/torchvision/datasets/mnist.py", line 137, in download
    if self._check_exists():
  File "/Users/beantown/opt/anaconda3/envs/PuzzleSolver/lib/python3.8/site-packages/torchvision/datasets/mnist.py", line 129, in _check_exists
    return (os.path.exists(os.path.join(self.processed_folder,
  File "/Users/beantown/opt/anaconda3/envs/PuzzleSolver/lib/python3.8/site-packages/torchvision/datasets/mnist.py", line 122, in processed_folder
    return os.path.join(self.root, self.__class__.__name__, 'processed')
  File "/Users/beantown/opt/anaconda3/envs/PuzzleSolver/lib/python3.8/posixpath.py", line 76, in join
    a = os.fspath(a)
TypeError: expected str, bytes or os.PathLike object, not int

