Failure # 1 (occurred at 2021-06-18_17-32-26)
Traceback (most recent call last):
  File "/Users/beantown/opt/anaconda3/envs/PuzzleSolver/lib/python3.8/site-packages/ray/tune/trial_runner.py", line 718, in _process_trial
    results = self.trial_executor.fetch_result(trial)
  File "/Users/beantown/opt/anaconda3/envs/PuzzleSolver/lib/python3.8/site-packages/ray/tune/ray_trial_executor.py", line 688, in fetch_result
    result = ray.get(trial_future[0], timeout=DEFAULT_GET_TIMEOUT)
  File "/Users/beantown/opt/anaconda3/envs/PuzzleSolver/lib/python3.8/site-packages/ray/_private/client_mode_hook.py", line 62, in wrapper
    return func(*args, **kwargs)
  File "/Users/beantown/opt/anaconda3/envs/PuzzleSolver/lib/python3.8/site-packages/ray/worker.py", line 1494, in get
    raise value.as_instanceof_cause()
ray.exceptions.RayTaskError(TuneError): [36mray::ImplicitFunc.train_buffered()[39m (pid=65057, ip=192.168.2.103)
  File "python/ray/_raylet.pyx", line 501, in ray._raylet.execute_task
  File "python/ray/_raylet.pyx", line 451, in ray._raylet.execute_task.function_executor
  File "/Users/beantown/opt/anaconda3/envs/PuzzleSolver/lib/python3.8/site-packages/ray/_private/function_manager.py", line 563, in actor_method_executor
    return method(__ray_actor, *args, **kwargs)
  File "/Users/beantown/opt/anaconda3/envs/PuzzleSolver/lib/python3.8/site-packages/ray/tune/trainable.py", line 173, in train_buffered
    result = self.train()
  File "/Users/beantown/opt/anaconda3/envs/PuzzleSolver/lib/python3.8/site-packages/ray/tune/trainable.py", line 232, in train
    result = self.step()
  File "/Users/beantown/opt/anaconda3/envs/PuzzleSolver/lib/python3.8/site-packages/ray/tune/function_runner.py", line 366, in step
    self._report_thread_runner_error(block=True)
  File "/Users/beantown/opt/anaconda3/envs/PuzzleSolver/lib/python3.8/site-packages/ray/tune/function_runner.py", line 512, in _report_thread_runner_error
    raise TuneError(
ray.tune.error.TuneError: Trial raised an exception. Traceback:
[36mray::ImplicitFunc.train_buffered()[39m (pid=65057, ip=192.168.2.103)
  File "/Users/beantown/opt/anaconda3/envs/PuzzleSolver/lib/python3.8/site-packages/ray/tune/function_runner.py", line 248, in run
    self._entrypoint()
  File "/Users/beantown/opt/anaconda3/envs/PuzzleSolver/lib/python3.8/site-packages/ray/tune/function_runner.py", line 315, in entrypoint
    return self._trainable_func(self.config, self._status_reporter,
  File "/Users/beantown/opt/anaconda3/envs/PuzzleSolver/lib/python3.8/site-packages/ray/tune/function_runner.py", line 580, in _trainable_func
    output = fn()
  File "/Users/beantown/opt/anaconda3/envs/PuzzleSolver/lib/python3.8/site-packages/ray/tune/utils/trainable.py", line 340, in _inner
    inner(config, checkpoint_dir=None)
  File "/Users/beantown/opt/anaconda3/envs/PuzzleSolver/lib/python3.8/site-packages/ray/tune/utils/trainable.py", line 331, in inner
    trainable(config, **fn_kwargs)
  File "/Users/beantown/PycharmProjects/jigsaw-puzzle-solver/src/Main.py", line 24, in training_function
    model = SiameseNetwork(config, data_dir)
  File "/Users/beantown/PycharmProjects/jigsaw-puzzle-solver/src/models/SiameseNetwork.py", line 30, in __init__
    self.train_data = SiameseNetworkDataset(
  File "/Users/beantown/PycharmProjects/jigsaw-puzzle-solver/src/SiameseNetworkDataset.py", line 13, in __init__
    self.df = pd.read_csv(csv_file)
  File "/Users/beantown/opt/anaconda3/envs/PuzzleSolver/lib/python3.8/site-packages/pandas/io/parsers.py", line 610, in read_csv
    return _read(filepath_or_buffer, kwds)
  File "/Users/beantown/opt/anaconda3/envs/PuzzleSolver/lib/python3.8/site-packages/pandas/io/parsers.py", line 462, in _read
    parser = TextFileReader(filepath_or_buffer, **kwds)
  File "/Users/beantown/opt/anaconda3/envs/PuzzleSolver/lib/python3.8/site-packages/pandas/io/parsers.py", line 819, in __init__
    self._engine = self._make_engine(self.engine)
  File "/Users/beantown/opt/anaconda3/envs/PuzzleSolver/lib/python3.8/site-packages/pandas/io/parsers.py", line 1050, in _make_engine
    return mapping[engine](self.f, **self.options)  # type: ignore[call-arg]
  File "/Users/beantown/opt/anaconda3/envs/PuzzleSolver/lib/python3.8/site-packages/pandas/io/parsers.py", line 1867, in __init__
    self._open_handles(src, kwds)
  File "/Users/beantown/opt/anaconda3/envs/PuzzleSolver/lib/python3.8/site-packages/pandas/io/parsers.py", line 1362, in _open_handles
    self.handles = get_handle(
  File "/Users/beantown/opt/anaconda3/envs/PuzzleSolver/lib/python3.8/site-packages/pandas/io/common.py", line 642, in get_handle
    handle = open(
FileNotFoundError: [Errno 2] No such file or directory: '/Users/beantown/PycharmProjects/jigsaw-puzzle-solver/data/KMNIST/rawtrain.csv'

