Failure # 1 (occurred at 2021-06-18_18-23-12)
Traceback (most recent call last):
  File "/Users/beantown/opt/anaconda3/envs/PuzzleSolver/lib/python3.8/site-packages/ray/tune/trial_runner.py", line 718, in _process_trial
    results = self.trial_executor.fetch_result(trial)
  File "/Users/beantown/opt/anaconda3/envs/PuzzleSolver/lib/python3.8/site-packages/ray/tune/ray_trial_executor.py", line 688, in fetch_result
    result = ray.get(trial_future[0], timeout=DEFAULT_GET_TIMEOUT)
  File "/Users/beantown/opt/anaconda3/envs/PuzzleSolver/lib/python3.8/site-packages/ray/_private/client_mode_hook.py", line 62, in wrapper
    return func(*args, **kwargs)
  File "/Users/beantown/opt/anaconda3/envs/PuzzleSolver/lib/python3.8/site-packages/ray/worker.py", line 1494, in get
    raise value.as_instanceof_cause()
ray.exceptions.RayTaskError(TuneError): [36mray::ImplicitFunc.train_buffered()[39m (pid=66635, ip=192.168.2.103)
  File "python/ray/_raylet.pyx", line 501, in ray._raylet.execute_task
  File "python/ray/_raylet.pyx", line 451, in ray._raylet.execute_task.function_executor
  File "/Users/beantown/opt/anaconda3/envs/PuzzleSolver/lib/python3.8/site-packages/ray/_private/function_manager.py", line 563, in actor_method_executor
    return method(__ray_actor, *args, **kwargs)
  File "/Users/beantown/opt/anaconda3/envs/PuzzleSolver/lib/python3.8/site-packages/ray/tune/trainable.py", line 173, in train_buffered
    result = self.train()
  File "/Users/beantown/opt/anaconda3/envs/PuzzleSolver/lib/python3.8/site-packages/ray/tune/trainable.py", line 232, in train
    result = self.step()
  File "/Users/beantown/opt/anaconda3/envs/PuzzleSolver/lib/python3.8/site-packages/ray/tune/function_runner.py", line 366, in step
    self._report_thread_runner_error(block=True)
  File "/Users/beantown/opt/anaconda3/envs/PuzzleSolver/lib/python3.8/site-packages/ray/tune/function_runner.py", line 512, in _report_thread_runner_error
    raise TuneError(
ray.tune.error.TuneError: Trial raised an exception. Traceback:
[36mray::ImplicitFunc.train_buffered()[39m (pid=66635, ip=192.168.2.103)
  File "/Users/beantown/opt/anaconda3/envs/PuzzleSolver/lib/python3.8/site-packages/ray/tune/function_runner.py", line 248, in run
    self._entrypoint()
  File "/Users/beantown/opt/anaconda3/envs/PuzzleSolver/lib/python3.8/site-packages/ray/tune/function_runner.py", line 315, in entrypoint
    return self._trainable_func(self.config, self._status_reporter,
  File "/Users/beantown/opt/anaconda3/envs/PuzzleSolver/lib/python3.8/site-packages/ray/tune/function_runner.py", line 580, in _trainable_func
    output = fn()
  File "/Users/beantown/opt/anaconda3/envs/PuzzleSolver/lib/python3.8/site-packages/ray/tune/utils/trainable.py", line 340, in _inner
    inner(config, checkpoint_dir=None)
  File "/Users/beantown/opt/anaconda3/envs/PuzzleSolver/lib/python3.8/site-packages/ray/tune/utils/trainable.py", line 331, in inner
    trainable(config, **fn_kwargs)
  File "/Users/beantown/PycharmProjects/jigsaw-puzzle-solver/src/Main.py", line 40, in training_function
    trainer.fit(model)
  File "/Users/beantown/opt/anaconda3/envs/PuzzleSolver/lib/python3.8/site-packages/mlflow/utils/autologging_utils/safety.py", line 489, in safe_patch_function
    patch_function(call_original, *args, **kwargs)
  File "/Users/beantown/opt/anaconda3/envs/PuzzleSolver/lib/python3.8/site-packages/mlflow/utils/autologging_utils/safety.py", line 240, in patch_with_managed_run
    result = patch_function(original, *args, **kwargs)
  File "/Users/beantown/opt/anaconda3/envs/PuzzleSolver/lib/python3.8/site-packages/mlflow/pytorch/_pytorch_autolog.py", line 303, in fit
    return _run_and_log_function(self, original, args, kwargs)
  File "/Users/beantown/opt/anaconda3/envs/PuzzleSolver/lib/python3.8/site-packages/mlflow/pytorch/_pytorch_autolog.py", line 295, in _run_and_log_function
    result = original(self, *args, **kwargs)
  File "/Users/beantown/opt/anaconda3/envs/PuzzleSolver/lib/python3.8/site-packages/mlflow/utils/autologging_utils/safety.py", line 445, in call_original
    original_result = original(*og_args, **og_kwargs)
  File "/Users/beantown/opt/anaconda3/envs/PuzzleSolver/lib/python3.8/site-packages/pytorch_lightning/trainer/trainer.py", line 458, in fit
    self._run(model)
  File "/Users/beantown/opt/anaconda3/envs/PuzzleSolver/lib/python3.8/site-packages/pytorch_lightning/trainer/trainer.py", line 756, in _run
    self.dispatch()
  File "/Users/beantown/opt/anaconda3/envs/PuzzleSolver/lib/python3.8/site-packages/pytorch_lightning/trainer/trainer.py", line 797, in dispatch
    self.accelerator.start_training(self)
  File "/Users/beantown/opt/anaconda3/envs/PuzzleSolver/lib/python3.8/site-packages/pytorch_lightning/accelerators/accelerator.py", line 96, in start_training
    self.training_type_plugin.start_training(trainer)
  File "/Users/beantown/opt/anaconda3/envs/PuzzleSolver/lib/python3.8/site-packages/pytorch_lightning/plugins/training_type/training_type_plugin.py", line 144, in start_training
    self._results = trainer.run_stage()
  File "/Users/beantown/opt/anaconda3/envs/PuzzleSolver/lib/python3.8/site-packages/pytorch_lightning/trainer/trainer.py", line 807, in run_stage
    return self.run_train()
  File "/Users/beantown/opt/anaconda3/envs/PuzzleSolver/lib/python3.8/site-packages/pytorch_lightning/trainer/trainer.py", line 842, in run_train
    self.run_sanity_check(self.lightning_module)
  File "/Users/beantown/opt/anaconda3/envs/PuzzleSolver/lib/python3.8/site-packages/pytorch_lightning/trainer/trainer.py", line 1107, in run_sanity_check
    self.run_evaluation()
  File "/Users/beantown/opt/anaconda3/envs/PuzzleSolver/lib/python3.8/site-packages/pytorch_lightning/trainer/trainer.py", line 962, in run_evaluation
    output = self.evaluation_loop.evaluation_step(batch, batch_idx, dataloader_idx)
  File "/Users/beantown/opt/anaconda3/envs/PuzzleSolver/lib/python3.8/site-packages/pytorch_lightning/trainer/evaluation_loop.py", line 174, in evaluation_step
    output = self.trainer.accelerator.validation_step(args)
  File "/Users/beantown/opt/anaconda3/envs/PuzzleSolver/lib/python3.8/site-packages/pytorch_lightning/accelerators/accelerator.py", line 226, in validation_step
    return self.training_type_plugin.validation_step(*args)
  File "/Users/beantown/opt/anaconda3/envs/PuzzleSolver/lib/python3.8/site-packages/pytorch_lightning/plugins/training_type/training_type_plugin.py", line 161, in validation_step
    return self.lightning_module.validation_step(*args, **kwargs)
  File "/Users/beantown/PycharmProjects/jigsaw-puzzle-solver/src/models/SiameseNetwork.py", line 91, in validation_step
    output1, output2 = self(x0, x1)
  File "/Users/beantown/opt/anaconda3/envs/PuzzleSolver/lib/python3.8/site-packages/torch/nn/modules/module.py", line 889, in _call_impl
    result = self.forward(*input, **kwargs)
  File "/Users/beantown/PycharmProjects/jigsaw-puzzle-solver/src/models/SiameseNetwork.py", line 79, in forward
    output1 = self.forward_once(input1)
  File "/Users/beantown/PycharmProjects/jigsaw-puzzle-solver/src/models/SiameseNetwork.py", line 73, in forward_once
    output = self.cnn1(x)
  File "/Users/beantown/opt/anaconda3/envs/PuzzleSolver/lib/python3.8/site-packages/torch/nn/modules/module.py", line 889, in _call_impl
    result = self.forward(*input, **kwargs)
  File "/Users/beantown/opt/anaconda3/envs/PuzzleSolver/lib/python3.8/site-packages/torch/nn/modules/container.py", line 119, in forward
    input = module(input)
  File "/Users/beantown/opt/anaconda3/envs/PuzzleSolver/lib/python3.8/site-packages/torch/nn/modules/module.py", line 889, in _call_impl
    result = self.forward(*input, **kwargs)
  File "/Users/beantown/opt/anaconda3/envs/PuzzleSolver/lib/python3.8/site-packages/torch/nn/modules/padding.py", line 173, in forward
    return F.pad(input, self.padding, 'reflect')
  File "/Users/beantown/opt/anaconda3/envs/PuzzleSolver/lib/python3.8/site-packages/torch/nn/functional.py", line 3995, in _pad
    assert len(pad) // 2 <= input.dim(), "Padding length too large"
AttributeError: 'str' object has no attribute 'dim'

