Failure # 1 (occurred at 2021-05-23_22-59-48)
Traceback (most recent call last):
  File "/Users/beantown/opt/anaconda3/envs/PuzzleSolver/lib/python3.8/site-packages/ray/tune/trial_runner.py", line 702, in _process_trial
    results = self.trial_executor.fetch_result(trial)
  File "/Users/beantown/opt/anaconda3/envs/PuzzleSolver/lib/python3.8/site-packages/ray/tune/ray_trial_executor.py", line 686, in fetch_result
    result = ray.get(trial_future[0], timeout=DEFAULT_GET_TIMEOUT)
  File "/Users/beantown/opt/anaconda3/envs/PuzzleSolver/lib/python3.8/site-packages/ray/_private/client_mode_hook.py", line 47, in wrapper
    return func(*args, **kwargs)
  File "/Users/beantown/opt/anaconda3/envs/PuzzleSolver/lib/python3.8/site-packages/ray/worker.py", line 1481, in get
    raise value.as_instanceof_cause()
ray.exceptions.RayTaskError(TuneError): [36mray::ImplicitFunc.train_buffered()[39m (pid=47258, ip=192.168.2.103)
  File "python/ray/_raylet.pyx", line 505, in ray._raylet.execute_task
  File "python/ray/_raylet.pyx", line 449, in ray._raylet.execute_task.function_executor
  File "/Users/beantown/opt/anaconda3/envs/PuzzleSolver/lib/python3.8/site-packages/ray/_private/function_manager.py", line 556, in actor_method_executor
    return method(__ray_actor, *args, **kwargs)
  File "/Users/beantown/opt/anaconda3/envs/PuzzleSolver/lib/python3.8/site-packages/ray/tune/trainable.py", line 173, in train_buffered
    result = self.train()
  File "/Users/beantown/opt/anaconda3/envs/PuzzleSolver/lib/python3.8/site-packages/ray/tune/trainable.py", line 232, in train
    result = self.step()
  File "/Users/beantown/opt/anaconda3/envs/PuzzleSolver/lib/python3.8/site-packages/ray/tune/function_runner.py", line 366, in step
    self._report_thread_runner_error(block=True)
  File "/Users/beantown/opt/anaconda3/envs/PuzzleSolver/lib/python3.8/site-packages/ray/tune/function_runner.py", line 512, in _report_thread_runner_error
    raise TuneError(
ray.tune.error.TuneError: Trial raised an exception. Traceback:
[36mray::ImplicitFunc.train_buffered()[39m (pid=47258, ip=192.168.2.103)
  File "/Users/beantown/opt/anaconda3/envs/PuzzleSolver/lib/python3.8/site-packages/ray/tune/function_runner.py", line 248, in run
    self._entrypoint()
  File "/Users/beantown/opt/anaconda3/envs/PuzzleSolver/lib/python3.8/site-packages/ray/tune/function_runner.py", line 315, in entrypoint
    return self._trainable_func(self.config, self._status_reporter,
  File "/Users/beantown/opt/anaconda3/envs/PuzzleSolver/lib/python3.8/site-packages/ray/tune/function_runner.py", line 580, in _trainable_func
    output = fn()
  File "/Users/beantown/opt/anaconda3/envs/PuzzleSolver/lib/python3.8/site-packages/ray/tune/utils/trainable.py", line 339, in _inner
    inner(config, checkpoint_dir=None)
  File "/Users/beantown/opt/anaconda3/envs/PuzzleSolver/lib/python3.8/site-packages/ray/tune/utils/trainable.py", line 330, in inner
    trainable(config, **fn_kwargs)
  File "/Users/beantown/PycharmProjects/jigsaw-puzzle-solver/src/Main.py", line 36, in training_function
    trainer.fit(model)
  File "/Users/beantown/opt/anaconda3/envs/PuzzleSolver/lib/python3.8/site-packages/pytorch_lightning/trainer/trainer.py", line 458, in fit
    self._run(model)
  File "/Users/beantown/opt/anaconda3/envs/PuzzleSolver/lib/python3.8/site-packages/pytorch_lightning/trainer/trainer.py", line 756, in _run
    self.dispatch()
  File "/Users/beantown/opt/anaconda3/envs/PuzzleSolver/lib/python3.8/site-packages/pytorch_lightning/trainer/trainer.py", line 797, in dispatch
    self.accelerator.start_training(self)
  File "/Users/beantown/opt/anaconda3/envs/PuzzleSolver/lib/python3.8/site-packages/pytorch_lightning/accelerators/accelerator.py", line 96, in start_training
    self.training_type_plugin.start_training(trainer)
  File "/Users/beantown/opt/anaconda3/envs/PuzzleSolver/lib/python3.8/site-packages/pytorch_lightning/plugins/training_type/training_type_plugin.py", line 144, in start_training
    self._results = trainer.run_stage()
  File "/Users/beantown/opt/anaconda3/envs/PuzzleSolver/lib/python3.8/site-packages/pytorch_lightning/trainer/trainer.py", line 807, in run_stage
    return self.run_train()
  File "/Users/beantown/opt/anaconda3/envs/PuzzleSolver/lib/python3.8/site-packages/pytorch_lightning/trainer/trainer.py", line 837, in run_train
    self._pre_training_routine()
  File "/Users/beantown/opt/anaconda3/envs/PuzzleSolver/lib/python3.8/site-packages/pytorch_lightning/trainer/trainer.py", line 822, in _pre_training_routine
    self.on_pretrain_routine_start()
  File "/Users/beantown/opt/anaconda3/envs/PuzzleSolver/lib/python3.8/site-packages/pytorch_lightning/trainer/callback_hook.py", line 162, in on_pretrain_routine_start
    callback.on_pretrain_routine_start(self, self.lightning_module)
  File "/Users/beantown/opt/anaconda3/envs/PuzzleSolver/lib/python3.8/site-packages/pytorch_lightning/callbacks/model_checkpoint.py", line 220, in on_pretrain_routine_start
    self.__resolve_ckpt_dir(trainer)
  File "/Users/beantown/opt/anaconda3/envs/PuzzleSolver/lib/python3.8/site-packages/pytorch_lightning/callbacks/model_checkpoint.py", line 584, in __resolve_ckpt_dir
    if isinstance(trainer.logger.version, str) else f"version_{trainer.logger.version}"
  File "/Users/beantown/opt/anaconda3/envs/PuzzleSolver/lib/python3.8/site-packages/pytorch_lightning/loggers/mlflow.py", line 232, in version
    return self.run_id
  File "/Users/beantown/opt/anaconda3/envs/PuzzleSolver/lib/python3.8/site-packages/pytorch_lightning/loggers/mlflow.py", line 163, in run_id
    _ = self.experiment
  File "/Users/beantown/opt/anaconda3/envs/PuzzleSolver/lib/python3.8/site-packages/pytorch_lightning/loggers/base.py", line 41, in experiment
    return get_experiment() or DummyExperiment()
  File "/Users/beantown/opt/anaconda3/envs/PuzzleSolver/lib/python3.8/site-packages/pytorch_lightning/utilities/distributed.py", line 49, in wrapped_fn
    return fn(*args, **kwargs)
  File "/Users/beantown/opt/anaconda3/envs/PuzzleSolver/lib/python3.8/site-packages/pytorch_lightning/loggers/base.py", line 39, in get_experiment
    return fn(self)
  File "/Users/beantown/opt/anaconda3/envs/PuzzleSolver/lib/python3.8/site-packages/pytorch_lightning/loggers/mlflow.py", line 150, in experiment
    self._experiment_id = self._mlflow_client.create_experiment(
  File "/Users/beantown/opt/anaconda3/envs/PuzzleSolver/lib/python3.8/site-packages/mlflow/tracking/client.py", line 471, in create_experiment
    return self._tracking_client.create_experiment(name, artifact_location)
  File "/Users/beantown/opt/anaconda3/envs/PuzzleSolver/lib/python3.8/site-packages/mlflow/tracking/_tracking_service/client.py", line 140, in create_experiment
    return self.store.create_experiment(name=name, artifact_location=artifact_location,)
  File "/Users/beantown/opt/anaconda3/envs/PuzzleSolver/lib/python3.8/site-packages/mlflow/store/tracking/rest_store.py", line 78, in create_experiment
    response_proto = self._call_endpoint(CreateExperiment, req_body)
  File "/Users/beantown/opt/anaconda3/envs/PuzzleSolver/lib/python3.8/site-packages/mlflow/store/tracking/rest_store.py", line 55, in _call_endpoint
    return call_endpoint(self.get_host_creds(), endpoint, method, json_body, response_proto)
  File "/Users/beantown/opt/anaconda3/envs/PuzzleSolver/lib/python3.8/site-packages/mlflow/utils/rest_utils.py", line 170, in call_endpoint
    response = verify_rest_response(response, endpoint)
  File "/Users/beantown/opt/anaconda3/envs/PuzzleSolver/lib/python3.8/site-packages/mlflow/utils/rest_utils.py", line 122, in verify_rest_response
    raise RestException(json.loads(response.text))
mlflow.exceptions.RestException: INVALID_PARAMETER_VALUE: Got an invalid experiment name 'Jiggsaw_test'. An experiment name must be an absolute path within the Databricks workspace, e.g. '/Users/<some-username>/my-experiment'. For more information about changes to experiment naming conventions, see 'https://docs.databricks.com/applications/mlflow/experiments.html#experiment-migration'.

